aiogram - WARNING - Updates were skipped successfully.
asyncio - ERROR - Task exception was never retrieved
future: <Task finished name='Task-12' coro=<Dispatcher._process_polling_updates() done, defined at D:\pythonProject\AideX\Lib\site-packages\aiogram\dispatcher\dispatcher.py:407> exception=NameError("name 'answer_n' is not defined")>
Traceback (most recent call last):
  File "D:\pythonProject\AideX\Lib\site-packages\aiogram\dispatcher\dispatcher.py", line 415, in _process_polling_updates
    for responses in itertools.chain.from_iterable(await self.process_updates(updates, fast)):
                                                   ^^^^^^^^^^^^^^^^^^^^^^^^^^^^^^^^^^^^^^^^^
  File "D:\pythonProject\AideX\Lib\site-packages\aiogram\dispatcher\dispatcher.py", line 235, in process_updates
    return await asyncio.gather(*tasks)
           ^^^^^^^^^^^^^^^^^^^^^^^^^^^^
  File "D:\pythonProject\AideX\Lib\site-packages\aiogram\dispatcher\handler.py", line 117, in notify
    response = await handler_obj.handler(*args, **partial_data)
               ^^^^^^^^^^^^^^^^^^^^^^^^^^^^^^^^^^^^^^^^^^^^^^^^
  File "D:\pythonProject\AideX\Lib\site-packages\aiogram\dispatcher\dispatcher.py", line 256, in process_update
    return await self.message_handlers.notify(update.message)
           ^^^^^^^^^^^^^^^^^^^^^^^^^^^^^^^^^^^^^^^^^^^^^^^^^^
  File "D:\pythonProject\AideX\Lib\site-packages\aiogram\dispatcher\handler.py", line 117, in notify
    response = await handler_obj.handler(*args, **partial_data)
               ^^^^^^^^^^^^^^^^^^^^^^^^^^^^^^^^^^^^^^^^^^^^^^^^
  File "D:\pythonProject\AideX\main.py", line 53, in answer_city
    user = User.get_chat(answer_n, answer_c, message.chat.id)# пользователь сохранен
                         ^^^^^^^^
NameError: name 'answer_n' is not defined
